<mujoco model="bit_door">
    <compiler angle="radian" meshdir="../meshes/bit_door/" />
    <size njmax="500" nconmax="100" />
    <default>
        <default class="collision">
          <geom condim="3" type="mesh" group="0" />
        </default>
        <default class="visual">
          <geom condim="3" type="mesh" group="1" conaffinity="0" contype="0" />
        </default>
    </default>
    <asset>
        <mesh name="door" file="door.stl" />
        <mesh name="handle" file="handle.stl" />
    </asset>
    <worldbody>
        <body name="door" pos="0 0 0">
            <inertial pos="-0.00724 0.441 1.029" mass="5" diaginertia="1 1 1" />
            <joint armature="0.01" name="door" pos="0 0 0" axis="0 0 1" limited="true" range="-3.14159 3.14159" />
            <geom type="mesh" contype="1" conaffinity="1" group="0" mesh="door" />
            <body name="handle" pos="-0.007 0.88 1.04" quat="0.5 -0.5 0.5 0.5">
                <inertial pos="0 -0.034 -0.015" mass="0.001" diaginertia="1 1 1" />
                <joint armature="0.001" stiffness="1.2" springref="0" name="handle" pos="0 0 0" axis="0 1 0" limited="true" range="-1.5708 0.1" />
                <geom type="mesh" contype="1" conaffinity="1" group="0" mesh="handle" />
            </body>
        </body>
    </worldbody>
</mujoco>
